Workbook

Sheet Form responses 1-compiled
B1: Q1 | D1: Q2 | F1: Q3 | H1: Q4 | J1: Q5 | L1: Q6 | N1: Q7 | P1: Q8 | R1: Q9 | S1: Q10 | U1: Q11 | W1: Q12 | X1: Q13 | Y1: Q13 | Z1: Q14 | AA1: Q14 | AB1: Q15 | AC1: Q15 | AD1: Q15 | AE1: Q16 | AF1: Q17 | AG1: Q17 | AI1: Q18 | AJ1: Q19 | AK1: Q20 | AL1: Q20 | AM1: Q21 | AN1: Q22 | AO1: Q23 | AP1: Q23 | AQ1: Q24 | AR1: Q24
A2: Timestamp | B2: Did you find it easy to find the required buttons? (1 for very hard and 10 for very easy) | C2: Any comment about the point? | D2: Did you recognize different icons and labels? (1 for very hard and 10 for very easy) | E2: Any comment about the point? | F2: Text and colors were easy for the eyes? (1 for no and 10 for yes) | G2: Any comment about the point? | H2: The application is easy to use with minimum instructions from the tester. (1 for no and 10 for yes) | I2: Any comment about the point? | J2: Steps are easy to follow, and buttons are easy to remember (1 for no and 10 for yes) | K2: Any comment about the point? | L2: You managed to finish the tasks as fast as possible. (1 for no and 10 for yes) | M2: Any comment about the point? | N2: Everything was clear and easy to preform without frustration (1 for no and 10 for yes) | O2: Any comment about the point? | P2: You managed to perform well in labs without difficulties in using the VR equipment | Q2: Any comment about the point? | R2: You managed to perform well in labs by hearing ROBO instructions and following them. | S2: ROBO instructions were clear and easy to follow | T2: Any comment about the point? | U2: Q3. You found the application interesting. (1 for no and 10 for yes) | V2: Any comment about the point? | W2: Q4. You found the gamification functions fun and encouraged competitive behavior. . (1 for no and 10 for yes) | X2: Was the application appealing in term of colors and visuals? | Y2: Was the application appealing in term of colors and visuals? | Z2: Was the navigation through the application easy and understandable? | AA2: Was the navigation through the application easy and understandable? | AB2: Was the interface crowded and hard to use? | AC2: Hardship | AD2: Opposite | AE2: Were the icons related to the information presented? | AF2: Does the app appearance consistent? | AI2: was the app fast to preform a task? | AJ2: Was it easy to go back to previous pages? | AK2: Could you use the application without instructions? | AL2: Could you use the application without instructions? | AM2: Did you manage to achieve the goal of the application? | AN2: What parts of the application did you think represented game aspects and were fun to experience? | AO2: Would you use the application in your education if available to you? | AP2: Would you use the application in your education if available to you? | AQ2: Would you recommend the application to other people? | AR2: Would you recommend the application to other people?
A3: 45357.411 | B3: 5 | C3: - | D3: 7 | E3: The text of small bottons that were on the board are soo small and not clear | F3: 7 | G3: Some colors weren't clear (especially when we had to wires) while when i had multiple wires they were clear | H3: 10 | I3: - | J3: 10 | K3: - | L3: 8 | M3: - | N3: 10 | O3: - | P3: 7 | R3: 10 | S3: 10 | U3: 10 | W3: 10 | X3: Yes it was so appealing and the colors/visuals were very attractive | Y3: 10 | Z3: Yes it was easy and understandable, once you get used to it becomes so much easier | AA3: 8 | AB3: No, the interface was easy to use and everything is well organized | AC3: 1 | AD3: =2*(6-AC3) -> 10 | AE3: Yes they were | AF3: Yes, the only problem was that the text was small for the small parts on the board | AG3: 7 | AH3: 1 | AI3: Yes | AJ3: Yes | AK3: Yes since there's a hint, you only need to use it for the first time with instructions later there's no need. | AL3: 9 | AM3: Yes | AN3: Everything was interesting and fun since I don't have any experience in labs. | AO3: Yes sure! | AP3: 10 | AQ3: Definitely yes! | AR3: 10
A4: 45357.45 | B4: 8 | C4: No everything easy | D4: 6 | E4: No | F4: 10 | G4: No it was easy | H4: 6 | I4: No | J4: 10 | K4: The hints helped me a lot and it was easy to follow | L4: 9 | M4: No | N4: 7 | O4: Sometimes it lagged but other things were good | P4: 7 | Q4: No | R4: 10 | S4: 10 | T4: The robot was easy to follow with | U4: 10 | V4: First time using this application it was fun | W4: 8 | X4: Yes the colors and visuals were good | Y4: 10 | Z4: Yes everything was simple and easy with ROBO the robot | AA4: 10 | AB4: No it was good | AC4: 1 | AD4: =2*(6-AC4) -> 10 | AE4: Yes all the information were related | AF4: Yes | AG4: 9 | AH4: 3 | AI4: Kind of yes it just lagged a bit | AJ4: Yes there was an exit button | AK4: No I used the instructions from the powerpoint | AL4: 7 | AM4: Yes | AN4: Putting all the chips and wires together | AO4: Yes it helped understanding me where all the wires went | AP4: 10 | AQ4: Yes | AR4: 8
A5: 45357.477 | B5: 3 | D5: 4 | F5: 8 | H5: 6 | J5: 9 | L5: 4 | N5: 3 | P5: 4 | R5: 7 | S5: 6 | U5: 10 | V5: Good luck on it 🩷 it is good but the vr tool little bit hard to use | W5: 4 | X5: Yes | Y5: 9 | Z5: Kind of yes | AA5: 7 | AB5: Hard to type in | AC5: 5 | AD5: =2*(6-AC5) -> 2 | AE5: Yes | AF5: Yes | AG5: 9 | AH5: 3 | AI5: No | AJ5: No | AK5: No | AL5: 5 | AM5: Kind of yes | AN5: Starting the circuit | AO5: Yes | AP5: 10 | AQ5: Yes for the it people | AR5: 8
A6: 45357.584 | B6: 9 | D6: 10 | F6: 7 | H6: 10 | J6: 10 | L6: 7 | M6: I suggest adding another hand | N6: 6 | O6: It was hard sometimes to focus | P6: 10 | R6: 10 | S6: 10 | T6: Robo was very helpful | U6: 10 | V6: I would like to use it in our labs | W6: 10 | X6: Yes | Y6: 9 | Z6: Yes | AA6: 8 | AB6: No | AC6: 1 | AD6: =2*(6-AC6) -> 10 | AE6: Yes | AF6: Yes | AG6: 9 | AH6: 3 | AI6: Sometime its hard | AJ6: Yes | AK6: Maybe after some time of practice | AL6: 6 | AM6: Yes | AN6: To get the result that i was excepting from the lab | AO6: Yes | AP6: 10 | AQ6: Yes definitely | AR6: 10
A7: 45357.615 | B7: 8 | D7: 7 | F7: 5 | G7: The colors weren't very clear they both looked black but I could separate them. And some writing was too small I couldn't read it | H7: 10 | J7: 10 | L7: 8 | N7: 10 | P7: 10 | R7: 10 | S7: 10 | T7: Maybe add captions to the wires so I know where to put them | U7: 10 | V7: Very interesting it was very fun | W7: 10 | X7: Yes | Y7: 9 | Z7: Yes very clear but the font was too small | AA7: 7 | AB7: No | AC7: 1 | AD7: =2*(6-AC7) -> 10 | AE7: Yes | AF7: Yes | AG7: 9 | AH7: 3 | AI7: Yes but a little laggy | AJ7: Not really it erased what I wrote before | AK7: Yes | AL7: 10 | AM7: Yes | AN7: I liked experimenting with the wires and doing the labs and I loved the leaderboard | AO7: Definitely it's very fun | AP7: 10 | AQ7: Yes | AR7: 8
A8: 45357.634 | B8: 10 | C8: No | D8: 10 | E8: No | F8: 10 | G8: No | H8: 10 | I8: No | J8: 10 | K8: No | L8: 10 | M8: No | N8: 10 | O8: No | P8: 10 | Q8: No | R8: 10 | S8: 10 | T8: No | U8: 10 | V8: No | W8: 10 | X8: Yes nice | Y8: 10 | Z8: Sureee | AA8: 9 | AB8: No | AC8: 1 | AD8: =2*(6-AC8) -> 10 | AE8: Yes | AF8: Stable | AG8: 8 | AH8: 2 | AI8: Yes | AJ8: Yes cool | AK8: Yes | AL8: 10 | AM8: Yep | AN8: Build | AO8: نعم ينفع جدا خصوصا للصغار | AP8: 10 | AQ8: لاشي | AR8: 6
A9: 45357.675 | B9: 9 | C9: somtimes when you click it slips to the other nearby buttons | D9: 10 | F9: 10 | H9: 10 | J9: 10 | L9: 10 | N9: 10 | P9: 9 | Q9: i think the colors of the wires should be a little but brighter | R9: 10 | S9: 10 | U9: 10 | W9: 10 | X9: yes, especially the little robot he was so cute, however the texts sometimes appears shaky especially when you move your head | Y9: 8 | Z9: it was very easy just like regular mobile apps | AA9: 9 | AB9: no, it was actually very simple and clear | AC9: 1 | AD9: =2*(6-AC9) -> 10 | AE9: yes it was obvious what they represent | AF9: yes, it’s consistent in style and doesn’t look patchy | AG9: 7 | AH9: 1 | AI9: yes, but i struggled a tiny bit while pressing buttons since it kinda slip, but overall it’s not that hard or frustrating | AJ9: yes you just click a simple back button | AK9: yes since it is clear and already has a cute little instructor (robo) | AL9: 10 | AM9: yes i built a fully functioning logical circuit | AN9: the limited hearts made me think twice about the placement so i don’t lose, and it’s fun to compete with your colleagues in the leaderboard | AO9: yes, it’s as good as the real lab | AP9: 10 | AQ9: definitely | AR9: 10
A10: 45357.773 | B10: 5 | D10: 10 | F10: 5 | H10: 8 | J10: 1 | L10: 1 | N10: 1 | P10: 1 | R10: 10 | S10: 10 | U10: 10 | W10: 10 | X10: Yes | Y10: 9 | Z10: Yes but by practicing | AA10: 8 | AB10: No | AC10: 1 | AD10: =2*(6-AC10) -> 10 | AE10: Yes | AF10: Yes | AG10: 9 | AH10: 3 | AI10: No, I had some difficulty to drag and drop the wires , but again I think by practicing it can be easier to done faster. | AJ10: Sometimes, I face difficulties to find back button because it doesn’t show up to me. It shows after I press multiples times. | AK10: Maybe | AL10: 7 | AM10: Yes | AN10: The physical board with wires and other components. | AO10: Yes, but I suggest to make in Arabic language also the other languages, and about the instructions,I don’t think it enough to understand the subject, put even though it can be improve it by time. | AP10: 10 | AQ10: Yes for sure | AR10: 8
A11: 45357.889 | B11: 6 | D11: 10 | E11: Perfect | F11: 8 | H11: 8 | J11: 9 | L11: 9 | N11: 8 | P11: 8 | R11: 9 | S11: 10 | U11: 10 | W11: 10 | X11: Yes | Y11: 9 | Z11: yes | AA11: 9 | AB11: No | AC11: 1 | AD11: =2*(6-AC11) -> 10 | AE11: Yes | AF11: Yes | AG11: 9 | AH11: 3 | AI11: yes | AJ11: yes | AK11: I think i need some help | AL11: 7 | AM11: Yes | AN11: Switching the LED ON AND OFF | AO11: Yes ofc | AP11: 10 | AQ11: yes | AR11: 8
A12: 45358.463 | B12: 10 | D12: 10 | F12: 7 | G12: The colors on the wires are a bit dark | H12: 8 | J12: 10 | L12: 10 | N12: 10 | P12: 10 | R12: 10 | S12: 10 | U12: 10 | W12: 10 | X12: Yes | Y12: 9 | Z12: Very easy | AA12: 10 | AB12: It wasn't crowder it was all organized and easy to use and easy to follow the instructions | AC12: 1 | AD12: =2*(6-AC12) -> 10 | AE12: Yes they were all related | AF12: It was all good and the appearance of the chips but the wire is a bit dark but still easy to know what color of yhe wire is | AG12: 7 | AH12: 2 | AI12: Yes | AJ12: Yes | AK12: Yes | AL12: 10 | AM12: Yes | AN12: The part were it showed me that I was wrong in some of the applications and I was very satisfied when it worked | AO12: Yes | AP12: 10 | AQ12: Yes, it helps a lot and shows how it can help knowing how a real bread board works | AR12: 10
A13: 45358.536 | B13: 5 | C13: Some buttons are a bit small maybe make them a bit bigger, sometimes there are many buttons so i get confused about which one to choose | D13: 10 | F13: 5 | G13: Yes it was easy for the eyes but the colors of the wires could be made clearer | H13: 8 | J13: 8 | L13: 9 | N13: 9 | P13: 9 | R13: 8 | S13: 8 | U13: 10 | W13: 10 | X13: Yes | Y13: 9 | Z13: Yes but sometimes i get confused which button to use | AA13: 7 | AB13: It was good | AC13: 1 | AD13: =2*(6-AC13) -> 10 | AE13: Yes | AF13: Yes but the sizes of text and buttons aren’t consistent | AG13: 7 | AH13: 2 | AI13: Yes | AJ13: I think so | AK13: Probably yes but it might take a bit of time | AL13: 8 | AM13: Yes | AN13: Learder board time and hearts | AO13: Yess , but i recommend not signing in with email as it takes time to type using vr, maybe use just the id of student | AP13: 8 | AQ13: Yess | AR13: 8
A14: 45358.558 | B14: 10 | D14: 10 | F14: 8 | G14: The texts are a bit unclear | H14: 10 | J14: 10 | L14: 8 | N14: 8 | P14: 10 | R14: 10 | S14: 10 | U14: 10 | W14: 10 | X14: Yes | Y14: 9 | Z14: Yes | AA14: 9 | AB14: No | AC14: 1 | AD14: =2*(6-AC14) -> 10 | AE14: Yes | AF14: Yes | AG14: 9 | AH14: 3 | AI14: It glitches when moving fast | AJ14: Yes | AK14: Yes | AL14: 10 | AM14: Yes | AN14: Performing the task was easy and well guided for someone who is playing for the first time | AO14: Yes, the application would make learning much more easier | AP14: 10 | AQ14: Yes | AR14: 8
A15: 45358.599 | B15: 8 | D15: 10 | F15: 8 | H15: 10 | J15: 10 | L15: 10 | N15: 10 | P15: 10 | R15: 10 | S15: 10 | U15: 10 | W15: 10 | X15: Yes but the light blue color is too light | Y15: 7 | Z15: Yes | AA15: 9 | AB15: No | AC15: 1 | AD15: =2*(6-AC15) -> 10 | AE15: Yes | AF15: Yes | AG15: 9 | AH15: 3 | AI15: Yes | AJ15: Yes | AK15: Yes | AL15: 10 | AM15: Yes | AN15: The way we can interact to build the circuit with instructions | AO15: Yes | AP15: 10 | AQ15: Yes to kids | AR15: 8
A16: 45358.698 | B16: 10 | D16: 9 | F16: 10 | G16: I like how the color is so comfy not red or that colors hurt your eyes | H16: 9 | J16: 10 | L16: 7 | M16: I tried to to do it correctly more that focusing in time | N16: 10 | P16: 10 | R16: 10 | S16: 10 | T16: I did know some information from my background but ROBO reminded me about point that I forget | U16: 10 | W16: 10 | X16: Yes ,it has clear and colorful colors with middle tone not high or low bright . | Y16: 6 | Z16: It was easy, but sometimes the click button (to go to next steps) I needed to be close more to the display to work successfully . | AA16: 6 | AB16: No , it has just what needed to be shown. | AC16: 1 | AD16: =2*(6-AC16) -> 10 | AE16: Yes , the tools of the experiment was close to the real ones. | AF16: Yes | AG16: 10 | AH16: 3 | AI16: Yes | AJ16: Yes , there was icon for going back | AK16: For me as IT Student yes I can , even for non IT students easy the application user friendly. | AL16: 9 | AM16: Yes | AN16: Part of experiment when putting the wires and gets into the breadboard | AO16: Of course, it’s explains everything relate to the course so well as the tools and what needed to use for + the rules of gates etc, it was so good for me. | AP16: 10 | AQ16: Yes they will get interest into VR &IT | AR16: 10
A17: 45358.721 | B17: 7 | C17: The structure of the wires needes fixing, it would be better if you provided real photos or demonstrational photos that would should show how it's implemented in real life and regarding to the placing of the wires signals I prefer you put a not on a side on what happened if you miss up or were the pin is heading in the breadboard | D17: 6 | E17: Just the arrangements of wires | F17: 2 | G17: Make it softer which is not too bright | H17: 5 | I17: No | J17: 6 | L17: 8 | M17: The more you get comfortable with the controls the better | N17: 5 | O17: Sometimes lags | P17: 7 | R17: 1 | S17: 8 | U17: 7 | W17: 10 | X17: No not really it was fine | Y17: 6 | Z17: Yeah | AA17: 9 | AB17: No | AC17: 1 | AD17: =2*(6-AC17) -> 10 | AE17: Yes | AF17: No needs fixing | AG17: 6 | AH17: 1 | AI17: No | AJ17: Yes there is a bit of a delay | AK17: No but yes without the voice | AL17: 6 | AM17: Yes | AN17: Placing wires | AO17: Yes | AP17: 10 | AQ17: Yes | AR17: 8
A18: 45358.768 | B18: 10 | D18: 10 | F18: 10 | H18: 10 | J18: 10 | L18: 10 | N18: 10 | P18: 10 | R18: 10 | S18: 10 | T18: He was cuteeee i liked him | U18: 10 | V18: I really likked the app , literally everything was amazing | W18: 10 | X18: Yes | Y18: 9 | Z18: Yes | AA18: 9 | AB18: nope | AC18: 1 | AD18: =2*(6-AC18) -> 10 | AE18: yess | AF18: Yeah | AG18: 10 | AH18: 3 | AI18: Reallly fastt | AJ18: Yess | AK18: Yes yes | AL18: 10 | AM18: Of course | AN18: Everything was enjoyable and fun | AO18: Yeahhh I really need it this course its really helpful | AP18: 10 | AQ18: I have already told my family also my friends about it 💗💗 | AR18: 10
A19: 45363.971 | B19: 10 | D19: 10 | F19: 10 | H19: 10 | J19: 10 | L19: 10 | N19: 10 | P19: 10 | R19: 10 | S19: 10 | U19: 10 | W19: 10 | X19: - | Y19: 5 | Z19: - | AA19: 5 | AB19: - | AC19: 3 | AD19: =2*(6-AC19) -> 6 | AE19: - | AF19: - | AG19: 5 | AH19: 2 | AI19: - | AJ19: - | AK19: - | AL19: 5 | AM19: - | AN19: - | AO19: - | AP19: 5 | AQ19: - | AR19: 5
A20: 45363.972 | B20: 10 | D20: 10 | F20: 10 | H20: 10 | J20: 10 | L20: 10 | N20: 10 | P20: 10 | R20: 10 | S20: 10 | U20: 10 | W20: 10 | X20: - | Y20: 5 | Z20: - | AA20: 5 | AB20: - | AC20: 3 | AD20: =2*(6-AC20) -> 6 | AE20: - | AF20: - | AG20: 5 | AH20: 2 | AI20: - | AJ20: - | AK20: - | AL20: 5 | AM20: - | AN20: - | AO20: - | AP20: 5 | AQ20: - | AR20: 5
A21: 45363.972 | B21: 10 | D21: 10 | F21: 10 | H21: 10 | J21: 10 | L21: 10 | N21: 10 | P21: 10 | R21: 10 | S21: 10 | U21: 10 | W21: 10 | X21: - | Y21: 5 | Z21: - | AA21: 5 | AB21: - | AC21: 3 | AD21: =2*(6-AC21) -> 6 | AE21: - | AF21: - | AG21: 5 | AH21: 2 | AI21: - | AJ21: - | AK21: - | AL21: 5 | AM21: - | AN21: - | AO21: - | AP21: 5 | AQ21: - | AR21: 5
A22: 45363.973 | B22: 10 | D22: 10 | F22: 10 | H22: 10 | J22: 10 | L22: 10 | N22: 10 | P22: 10 | R22: 10 | S22: 10 | U22: 10 | W22: 10 | X22: - | Y22: 5 | Z22: - | AA22: 5 | AB22: - | AC22: 4 | AD22: =2*(6-AC22) -> 4 | AE22: - | AF22: - | AG22: 5 | AH22: 2 | AI22: - | AJ22: - | AK22: - | AL22: 5 | AM22: - | AN22: - | AO22: - | AP22: 5 | AQ22: - | AR22: 5
A23: 45363.974 | B23: 10 | D23: 10 | F23: 10 | H23: 10 | J23: 10 | L23: 10 | N23: 10 | P23: 10 | R23: 10 | S23: 10 | U23: 10 | W23: 10 | X23: - | Y23: 5 | Z23: - | AA23: 5 | AB23: - | AC23: 4 | AD23: =2*(6-AC23) -> 4 | AE23: - | AF23: - | AG23: 5 | AH23: 2 | AI23: - | AJ23: - | AK23: - | AL23: 5 | AM23: - | AN23: - | AO23: - | AP23: 5 | AQ23: - | AR23: 5
A24: 45363.975 | B24: 10 | D24: 10 | F24: 10 | H24: 10 | J24: 10 | L24: 10 | N24: 10 | P24: 10 | R24: 10 | S24: 10 | U24: 10 | W24: 10 | X24: - | Y24: 5 | Z24: - | AA24: 5 | AB24: - | AC24: 4 | AD24: =2*(6-AC24) -> 4 | AE24: - | AF24: - | AG24: 5 | AH24: 2 | AI24: - | AJ24: - | AK24: - | AL24: 5 | AM24: - | AN24: - | AO24: - | AP24: 5 | AQ24: - | AR24: 5
A26: Mean | B26: =AVERAGE(B3:B24) -> 8.3181818 | C26: =AVERAGE(C3:C24) -> #DIV/0! | D26: =AVERAGE(D3:D24) -> 9.0454545 | E26: =AVERAGE(E3:E24) -> #DIV/0! | F26: =AVERAGE(F3:F24) -> 8.1818182 | G26: =AVERAGE(G3:G24) -> #DIV/0! | H26: =AVERAGE(H3:H24) -> 9 | I26: =AVERAGE(I3:I24) -> #DIV/0! | ... AB26: =AVERAGE(AB3:AB24) -> #DIV/0! | AD26: =AVERAGE(AD3:AD24) -> 8.2727273 | AE26: =AVERAGE(AE3:AE24) -> #DIV/0! | AF26: =AVERAGE(AF3:AF24) -> #DIV/0! | AG26: =AVERAGE(AG3:AG24) -> 7.4545455 | AH26: =10*AVERAGE(AH3:AH24)/3 -> 7.7272727 | AI26: =AVERAGE(AI3:AI24) -> #DIV/0! | AJ26: =AVERAGE(AJ3:AJ24) -> #DIV/0! | AK26: =AVERAGE(AK3:AK24) -> #DIV/0! | AL26: =AVERAGE(AL3:AL24) -> 7.4545455 | AM26: =AVERAGE(AM3:AM24) -> #DIV/0! | AN26: =AVERAGE(AN3:AN24) -> #DIV/0! | AO26: =AVERAGE(AO3:AO24) -> #DIV/0! | AP26: =AVERAGE(AP3:AP24) -> 8.5454545 | ... AR26: =AVERAGE(AR3:AR24) -> 7.6363636
A27: STD | B27: =_xlfn.STDEV.S(B3:B24) -> 2.1905938 | C27: =_xlfn.STDEV.S(C3:C24) -> #DIV/0! | D27: =_xlfn.STDEV.S(D3:D24) -> 1.7855844 | E27: =_xlfn.STDEV.S(E3:E24) -> #DIV/0! | F27: =_xlfn.STDEV.S(F3:F24) -> 2.2811101 | G27: =_xlfn.STDEV.S(G3:G24) -> #DIV/0! | H27: =_xlfn.STDEV.S(H3:H24) -> 1.5735916 | I27: =_xlfn.STDEV.S(I3:I24) -> #DIV/0! | ... AB27: =_xlfn.STDEV.S(AB3:AB24) -> #DIV/0! | AD27: =_xlfn.STDEV.S(AD3:AD24) -> 2.7112081 | AE27: =_xlfn.STDEV.S(AE3:AE24) -> #DIV/0! | AF27: =_xlfn.STDEV.S(AF3:AF24) -> #DIV/0! | AG27: =_xlfn.STDEV.S(AG3:AG24) -> 1.8446131 | AH27: =10*_xlfn.STDEV.S(AH3:AH24)/3 -> 2.3874371 | AI27: =_xlfn.STDEV.S(AI3:AI24) -> #DIV/0! | AJ27: =_xlfn.STDEV.S(AJ3:AJ24) -> #DIV/0! | AK27: =_xlfn.STDEV.S(AK3:AK24) -> #DIV/0! | AL27: =_xlfn.STDEV.S(AL3:AL24) -> 2.1542267 | AM27: =_xlfn.STDEV.S(AM3:AM24) -> #DIV/0! | AN27: =_xlfn.STDEV.S(AN3:AN24) -> #DIV/0! | AO27: =_xlfn.STDEV.S(AO3:AO24) -> #DIV/0! | AP27: =_xlfn.STDEV.S(AP3:AP24) -> 2.2620529 | ... AR27: =_xlfn.STDEV.S(AR3:AR24) -> 1.9406787
Q29: sample =23 | R29: one sample t-test
Q30: Hypothetical mean value=7
H31: Q4. Learnability | I31: Q4. Learnablity % | J31: Q5. Memorability | K31: Q5. Memorability % | L31: Q6. Performance | M31: Q6. Performance % | Q31: Question | R31: AVG | S31: STD | T31: SEM | U31: p-value
G32: 1 | H32: =COUNTIF($H$3:$H$24,G32) -> 0 | J32: =COUNTIF($J$3:$J$24,G32) -> 1 | K32: =J32/22 -> 0.045454545 | L32: =COUNTIF($L$3:$L$24,G32) -> 1 | M32: =L32/22 -> 0.045454545 | Q32: Q1 | R32: 8.5 | S32: 2.57 | T32: 0.535 | U32: 0.0105
G33: 2 | H33: =COUNTIF($H$3:$H$24,G33) -> 0 | J33: =COUNTIF($J$3:$J$24,G33) -> 0 | L33: =COUNTIF($L$3:$L$24,G33) -> 0 | Q33: Q2 | R33: 8.72 | S33: 2.33 | T33: 0.486 | U33: 0.0018
G34: 3 | H34: =COUNTIF($H$3:$H$24,G34) -> 0 | J34: =COUNTIF($J$3:$J$24,G34) -> 0 | L34: =COUNTIF($L$3:$L$24,G34) -> 0 | Q34: Q3 | R34: 9.86 | S34: 0.63 | T34: 0.13 | U34: 0.0001
G35: 4 | H35: =COUNTIF($H$3:$H$24,G35) -> 0 | J35: =COUNTIF($J$3:$J$24,G35) -> 0 | L35: =COUNTIF($L$3:$L$24,G35) -> 1 | M35: =L35/22 -> 0.045454545 | Q35: Q4 | R35: 9.63 | S35: 1.32 | T35: 0.275 | U35: 0.0001
G36: 5 | H36: =COUNTIF($H$3:$H$24,G36) -> 1 | I36: =H36/22 -> 0.045454545 | J36: =COUNTIF($J$3:$J$24,G36) -> 0 | L36: =COUNTIF($L$3:$L$24,G36) -> 0
G37: 6 | H37: =COUNTIF($H$3:$H$24,G37) -> 2 | I37: =H37/22 -> 0.090909091 | J37: =COUNTIF($J$3:$J$24,G37) -> 1 | K37: =J37/22 -> 0.045454545 | L37: =COUNTIF($L$3:$L$24,G37) -> 0
G38: 7 | H38: =COUNTIF($H$3:$H$24,G38) -> 0 | J38: =COUNTIF($J$3:$J$24,G38) -> 0 | L38: =COUNTIF($L$3:$L$24,G38) -> 2 | M38: =L38/22 -> 0.090909091 | R38: =AVERAGE(R32:R35) -> 9.1775
G39: 8 | H39: =COUNTIF($H$3:$H$24,G39) -> 4 | I39: =H39/22 -> 0.18181818 | J39: =COUNTIF($J$3:$J$24,G39) -> 1 | K39: =J39/22 -> 0.045454545 | L39: =COUNTIF($L$3:$L$24,G39) -> 4 | M39: =L39/22 -> 0.18181818
G40: 9 | H40: =COUNTIF($H$3:$H$24,G40) -> 1 | I40: =H40/22 -> 0.045454545 | J40: =COUNTIF($J$3:$J$24,G40) -> 2 | K40: =J40/22 -> 0.090909091 | L40: =COUNTIF($L$3:$L$24,G40) -> 3 | M40: =L40/22 -> 0.13636364
G41: 10 | H41: =COUNTIF($H$3:$H$24,G41) -> 14 | I41: =H41/22 -> 0.63636364 | J41: =COUNTIF($J$3:$J$24,G41) -> 17 | K41: =J41/22 -> 0.77272727 | L41: =COUNTIF($L$3:$L$24,G41) -> 11 | M41: =L41/22 -> 0.5
H45: Q7. Tension and Frustration | I45: % | J45: Q8. Usage of VR Equipment | L45: Q9. Robo Instructions & Hints
...

Sheet Form responses 1-means-std
B1: Q1 | D1: Q2 | F1: Q3 | H1: Q4 | J1: Q5 | L1: Q6 | N1: Q7 | P1: Q8 | R1: Q9 | S1: Q10 | U1: Q11 | W1: Q12 | X1: Q13 | Y1: Q13 | Z1: Q14 | AA1: Q14 | AB1: Q15 | AC1: Q15 | AD1: Q15 | AE1: Q16 | AF1: Q17 | AG1: Q17 | AI1: Q18 | AJ1: Q19 | AK1: Q20 | AL1: Q20 | AM1: Q21 | AN1: Q22 | AO1: Q23 | AP1: Q23 | AQ1: Q24 | AR1: Q24
A2: Timestamp | B2: Did you find it easy to find the required buttons? (1 for very hard and 10 for very easy) | C2: Any comment about the point? | D2: Did you recognize different icons and labels? (1 for very hard and 10 for very easy) | E2: Any comment about the point? | F2: Text and colors were easy for the eyes? (1 for no and 10 for yes) | G2: Any comment about the point? | H2: The application is easy to use with minimum instructions from the tester. (1 for no and 10 for yes) | I2: Any comment about the point? | J2: Steps are easy to follow, and buttons are easy to remember (1 for no and 10 for yes) | K2: Any comment about the point? | L2: You managed to finish the tasks as fast as possible. (1 for no and 10 for yes) | M2: Any comment about the point? | N2: Q1.Everything was clear and easy to preform without frustration (1 for no and 10 for yes) | O2: Any comment about the point? | P2: You managed to perform well in labs without difficulties in using the VR equipment | Q2: Any comment about the point? | R2: You managed to perform well in labs by hearing ROBO instructions and following them. | S2: ROBO instructions were clear and easy to follow | T2: Any comment about the point? | U2: Q3. You found the application interesting. (1 for no and 10 for yes) | V2: Any comment about the point? | W2: Q4. You found the gamification functions fun and encouraged competitive behavior. . (1 for no and 10 for yes) | X2: Was the application appealing in term of colors and visuals? | Y2: Was the application appealing in term of colors and visuals? | Z2: Was the navigation through the application easy and understandable? | AA2: Was the navigation through the application easy and understandable? | AB2: Was the interface crowded and hard to use? | AC2: Hardship | AD2: Opposite | AE2: Were the icons related to the information presented? | AF2: Does the app appearance consistent? | AI2: was the app fast to preform a task? | AJ2: Was it easy to go back to previous pages? | AK2: Could you use the application without instructions? | AL2: Could you use the application without instructions? | AM2: Did you manage to achieve the goal of the application? | AN2: What parts of the application did you think represented game aspects and were fun to experience? | AO2: Would you use the application in your education if available to you? | AP2: Would you use the application in your education if available to you? | AQ2: Would you recommend the application to other people? | AR2: Would you recommend the application to other people?
A3: 45357.411 | B3: 5 | C3: - | D3: 7 | E3: The text of small bottons that were on the board are soo small and not clear | F3: 7 | G3: Some colors weren't clear (especially when we had to wires) while when i had multiple wires they were clear | H3: 10 | I3: - | J3: 10 | K3: - | L3: 8 | M3: - | N3: 10 | O3: - | P3: 7 | R3: 10 | S3: 10 | U3: 10 | W3: 10 | X3: Yes it was so appealing and the colors/visuals were very attractive | Y3: 10 | Z3: Yes it was easy and understandable, once you get used to it becomes so much easier | AA3: 8 | AB3: No, the interface was easy to use and everything is well organized | AC3: 1 | AD3: =2*(6-AC3) -> 10 | AE3: Yes they were | AF3: Yes, the only problem was that the text was small for the small parts on the board | AG3: 7 | AH3: 1 | AI3: Yes | AJ3: Yes | AK3: Yes since there's a hint, you only need to use it for the first time with instructions later there's no need. | AL3: 9 | AM3: Yes | AN3: Everything was interesting and fun since I don't have any experience in labs. | AO3: Yes sure! | AP3: 10 | AQ3: Definitely yes! | AR3: 10
A4: 45357.45 | B4: 8 | C4: No everything easy | D4: 6 | E4: No | F4: 10 | G4: No it was easy | H4: 6 | I4: No | J4: 10 | K4: The hints helped me a lot and it was easy to follow | L4: 9 | M4: No | N4: 7 | O4: Sometimes it lagged but other things were good | P4: 7 | Q4: No | R4: 10 | S4: 10 | T4: The robot was easy to follow with | U4: 10 | V4: First time using this application it was fun | W4: 8 | X4: Yes the colors and visuals were good | Y4: 10 | Z4: Yes everything was simple and easy with ROBO the robot | AA4: 10 | AB4: No it was good | AC4: 1 | AD4: =2*(6-AC4) -> 10 | AE4: Yes all the information were related | AF4: Yes | AG4: 9 | AH4: 3 | AI4: Kind of yes it just lagged a bit | AJ4: Yes there was an exit button | AK4: No I used the instructions from the powerpoint | AL4: 7 | AM4: Yes | AN4: Putting all the chips and wires together | AO4: Yes it helped understanding me where all the wires went | AP4: 10 | AQ4: Yes | AR4: 8
A5: 45357.477 | B5: 3 | D5: 4 | F5: 8 | H5: 6 | J5: 9 | L5: 4 | N5: 3 | P5: 4 | R5: 7 | S5: 6 | U5: 10 | V5: Good luck on it 🩷 it is good but the vr tool little bit hard to use | W5: 4 | X5: Yes | Y5: 9 | Z5: Kind of yes | AA5: 7 | AB5: Hard to type in | AC5: 5 | AD5: =2*(6-AC5) -> 2 | AE5: Yes | AF5: Yes | AG5: 9 | AH5: 3 | AI5: No | AJ5: No | AK5: No | AL5: 5 | AM5: Kind of yes | AN5: Starting the circuit | AO5: Yes | AP5: 10 | AQ5: Yes for the it people | AR5: 8
A6: 45357.584 | B6: 9 | D6: 10 | F6: 7 | H6: 10 | J6: 10 | L6: 7 | M6: I suggest adding another hand | N6: 6 | O6: It was hard sometimes to focus | P6: 10 | R6: 10 | S6: 10 | T6: Robo was very helpful | U6: 10 | V6: I would like to use it in our labs | W6: 10 | X6: Yes | Y6: 9 | Z6: Yes | AA6: 8 | AB6: No | AC6: 1 | AD6: =2*(6-AC6) -> 10 | AE6: Yes | AF6: Yes | AG6: 9 | AH6: 3 | AI6: Sometime its hard | AJ6: Yes | AK6: Maybe after some time of practice | AL6: 6 | AM6: Yes | AN6: To get the result that i was excepting from the lab | AO6: Yes | AP6: 10 | AQ6: Yes definitely | AR6: 10
A7: 45357.615 | B7: 8 | D7: 7 | F7: 5 | G7: The colors weren't very clear they both looked black but I could separate them. And some writing was too small I couldn't read it | H7: 10 | J7: 10 | L7: 8 | N7: 10 | P7: 10 | R7: 10 | S7: 10 | T7: Maybe add captions to the wires so I know where to put them | U7: 10 | V7: Very interesting it was very fun | W7: 10 | X7: Yes | Y7: 9 | Z7: Yes very clear but the font was too small | AA7: 7 | AB7: No | AC7: 1 | AD7: =2*(6-AC7) -> 10 | AE7: Yes | AF7: Yes | AG7: 9 | AH7: 3 | AI7: Yes but a little laggy | AJ7: Not really it erased what I wrote before | AK7: Yes | AL7: 10 | AM7: Yes | AN7: I liked experimenting with the wires and doing the labs and I loved the leaderboard | AO7: Definitely it's very fun | AP7: 10 | AQ7: Yes | AR7: 8
A8: 45357.634 | B8: 10 | C8: No | D8: 10 | E8: No | F8: 10 | G8: No | H8: 10 | I8: No | J8: 10 | K8: No | L8: 10 | M8: No | N8: 10 | O8: No | P8: 10 | Q8: No | R8: 10 | S8: 10 | T8: No | U8: 10 | V8: No | W8: 10 | X8: Yes nice | Y8: 10 | Z8: Sureee | AA8: 9 | AB8: No | AC8: 1 | AD8: =2*(6-AC8) -> 10 | AE8: Yes | AF8: Stable | AG8: 8 | AH8: 2 | AI8: Yes | AJ8: Yes cool | AK8: Yes | AL8: 10 | AM8: Yep | AN8: Build | AO8: نعم ينفع جدا خصوصا للصغار | AP8: 10 | AQ8: لاشي | AR8: 6
A9: 45357.675 | B9: 9 | C9: somtimes when you click it slips to the other nearby buttons | D9: 10 | F9: 10 | H9: 10 | J9: 10 | L9: 10 | N9: 10 | P9: 9 | Q9: i think the colors of the wires should be a little but brighter | R9: 10 | S9: 10 | U9: 10 | W9: 10 | X9: yes, especially the little robot he was so cute, however the texts sometimes appears shaky especially when you move your head | Y9: 8 | Z9: it was very easy just like regular mobile apps | AA9: 9 | AB9: no, it was actually very simple and clear | AC9: 1 | AD9: =2*(6-AC9) -> 10 | AE9: yes it was obvious what they represent | AF9: yes, it’s consistent in style and doesn’t look patchy | AG9: 7 | AH9: 1 | AI9: yes, but i struggled a tiny bit while pressing buttons since it kinda slip, but overall it’s not that hard or frustrating | AJ9: yes you just click a simple back button | AK9: yes since it is clear and already has a cute little instructor (robo) | AL9: 10 | AM9: yes i built a fully functioning logical circuit | AN9: the limited hearts made me think twice about the placement so i don’t lose, and it’s fun to compete with your colleagues in the leaderboard | AO9: yes, it’s as good as the real lab | AP9: 10 | AQ9: definitely | AR9: 10
A10: 45357.773 | B10: 5 | D10: 10 | F10: 5 | H10: 8 | J10: 1 | L10: 1 | N10: 1 | P10: 1 | R10: 10 | S10: 10 | U10: 10 | W10: 10 | X10: Yes | Y10: 9 | Z10: Yes but by practicing | AA10: 8 | AB10: No | AC10: 1 | AD10: =2*(6-AC10) -> 10 | AE10: Yes | AF10: Yes | AG10: 9 | AH10: 3 | AI10: No, I had some difficulty to drag and drop the wires , but again I think by practicing it can be easier to done faster. | AJ10: Sometimes, I face difficulties to find back button because it doesn’t show up to me. It shows after I press multiples times. | AK10: Maybe | AL10: 7 | AM10: Yes | AN10: The physical board with wires and other components. | AO10: Yes, but I suggest to make in Arabic language also the other languages, and about the instructions,I don’t think it enough to understand the subject, put even though it can be improve it by time. | AP10: 10 | AQ10: Yes for sure | AR10: 8
A11: 45357.889 | B11: 6 | D11: 10 | E11: Perfect | F11: 8 | H11: 8 | J11: 9 | L11: 9 | N11: 8 | P11: 8 | R11: 9 | S11: 10 | U11: 10 | W11: 10 | X11: Yes | Y11: 9 | Z11: yes | AA11: 9 | AB11: No | AC11: 1 | AD11: =2*(6-AC11) -> 10 | AE11: Yes | AF11: Yes | AG11: 9 | AH11: 3 | AI11: yes | AJ11: yes | AK11: I think i need some help | AL11: 7 | AM11: Yes | AN11: Switching the LED ON AND OFF | AO11: Yes ofc | AP11: 10 | AQ11: yes | AR11: 8
A12: 45358.463 | B12: 10 | D12: 10 | F12: 7 | G12: The colors on the wires are a bit dark | H12: 8 | J12: 10 | L12: 10 | N12: 10 | P12: 10 | R12: 10 | S12: 10 | U12: 10 | W12: 10 | X12: Yes | Y12: 9 | Z12: Very easy | AA12: 10 | AB12: It wasn't crowder it was all organized and easy to use and easy to follow the instructions | AC12: 1 | AD12: =2*(6-AC12) -> 10 | AE12: Yes they were all related | AF12: It was all good and the appearance of the chips but the wire is a bit dark but still easy to know what color of yhe wire is | AG12: 7 | AH12: 2 | AI12: Yes | AJ12: Yes | AK12: Yes | AL12: 10 | AM12: Yes | AN12: The part were it showed me that I was wrong in some of the applications and I was very satisfied when it worked | AO12: Yes | AP12: 10 | AQ12: Yes, it helps a lot and shows how it can help knowing how a real bread board works | AR12: 10
A13: 45358.536 | B13: 5 | C13: Some buttons are a bit small maybe make them a bit bigger, sometimes there are many buttons so i get confused about which one to choose | D13: 10 | F13: 5 | G13: Yes it was easy for the eyes but the colors of the wires could be made clearer | H13: 8 | J13: 8 | L13: 9 | N13: 9 | P13: 9 | R13: 8 | S13: 8 | U13: 10 | W13: 10 | X13: Yes | Y13: 9 | Z13: Yes but sometimes i get confused which button to use | AA13: 7 | AB13: It was good | AC13: 1 | AD13: =2*(6-AC13) -> 10 | AE13: Yes | AF13: Yes but the sizes of text and buttons aren’t consistent | AG13: 7 | AH13: 2 | AI13: Yes | AJ13: I think so | AK13: Probably yes but it might take a bit of time | AL13: 8 | AM13: Yes | AN13: Learder board time and hearts | AO13: Yess , but i recommend not signing in with email as it takes time to type using vr, maybe use just the id of student | AP13: 8 | AQ13: Yess | AR13: 8
A14: 45358.558 | B14: 10 | D14: 10 | F14: 8 | G14: The texts are a bit unclear | H14: 10 | J14: 10 | L14: 8 | N14: 8 | P14: 10 | R14: 10 | S14: 10 | U14: 10 | W14: 10 | X14: Yes | Y14: 9 | Z14: Yes | AA14: 9 | AB14: No | AC14: 1 | AD14: =2*(6-AC14) -> 10 | AE14: Yes | AF14: Yes | AG14: 9 | AH14: 3 | AI14: It glitches when moving fast | AJ14: Yes | AK14: Yes | AL14: 10 | AM14: Yes | AN14: Performing the task was easy and well guided for someone who is playing for the first time | AO14: Yes, the application would make learning much more easier | AP14: 10 | AQ14: Yes | AR14: 8
A15: 45358.599 | B15: 8 | D15: 10 | F15: 8 | H15: 10 | J15: 10 | L15: 10 | N15: 10 | P15: 10 | R15: 10 | S15: 10 | U15: 10 | W15: 10 | X15: Yes but the light blue color is too light | Y15: 7 | Z15: Yes | AA15: 9 | AB15: No | AC15: 1 | AD15: =2*(6-AC15) -> 10 | AE15: Yes | AF15: Yes | AG15: 9 | AH15: 3 | AI15: Yes | AJ15: Yes | AK15: Yes | AL15: 10 | AM15: Yes | AN15: The way we can interact to build the circuit with instructions | AO15: Yes | AP15: 10 | AQ15: Yes to kids | AR15: 8
A16: 45358.698 | B16: 10 | D16: 9 | F16: 10 | G16: I like how the color is so comfy not red or that colors hurt your eyes | H16: 9 | J16: 10 | L16: 7 | M16: I tried to to do it correctly more that focusing in time | N16: 10 | P16: 10 | R16: 10 | S16: 10 | T16: I did know some information from my background but ROBO reminded me about point that I forget | U16: 10 | W16: 10 | X16: Yes ,it has clear and colorful colors with middle tone not high or low bright . | Y16: 6 | Z16: It was easy, but sometimes the click button (to go to next steps) I needed to be close more to the display to work successfully . | AA16: 6 | AB16: No , it has just what needed to be shown. | AC16: 1 | AD16: =2*(6-AC16) -> 10 | AE16: Yes , the tools of the experiment was close to the real ones. | AF16: Yes | AG16: 10 | AH16: 3 | AI16: Yes | AJ16: Yes , there was icon for going back | AK16: For me as IT Student yes I can , even for non IT students easy the application user friendly. | AL16: 9 | AM16: Yes | AN16: Part of experiment when putting the wires and gets into the breadboard | AO16: Of course, it’s explains everything relate to the course so well as the tools and what needed to use for + the rules of gates etc, it was so good for me. | AP16: 10 | AQ16: Yes they will get interest into VR &IT | AR16: 10
A17: 45358.721 | B17: 7 | C17: The structure of the wires needes fixing, it would be better if you provided real photos or demonstrational photos that would should show how it's implemented in real life and regarding to the placing of the wires signals I prefer you put a not on a side on what happened if you miss up or were the pin is heading in the breadboard | D17: 6 | E17: Just the arrangements of wires | F17: 2 | G17: Make it softer which is not too bright | H17: 5 | I17: No | J17: 6 | L17: 8 | M17: The more you get comfortable with the controls the better | N17: 5 | O17: Sometimes lags | P17: 7 | R17: 1 | S17: 8 | U17: 7 | W17: 10 | X17: No not really it was fine | Y17: 6 | Z17: Yeah | AA17: 9 | AB17: No | AC17: 1 | AD17: =2*(6-AC17) -> 10 | AE17: Yes | AF17: No needs fixing | AG17: 6 | AH17: 1 | AI17: No | AJ17: Yes there is a bit of a delay | AK17: No but yes without the voice | AL17: 6 | AM17: Yes | AN17: Placing wires | AO17: Yes | AP17: 10 | AQ17: Yes | AR17: 8
A18: 45358.768 | B18: 10 | D18: 10 | F18: 10 | H18: 10 | J18: 10 | L18: 10 | N18: 10 | P18: 10 | R18: 10 | S18: 10 | T18: He was cuteeee i liked him | U18: 10 | V18: I really likked the app , literally everything was amazing | W18: 10 | X18: Yes | Y18: 9 | Z18: Yes | AA18: 9 | AB18: nope | AC18: 1 | AD18: =2*(6-AC18) -> 10 | AE18: yess | AF18: Yeah | AG18: 10 | AH18: 3 | AI18: Reallly fastt | AJ18: Yess | AK18: Yes yes | AL18: 10 | AM18: Of course | AN18: Everything was enjoyable and fun | AO18: Yeahhh I really need it this course its really helpful | AP18: 10 | AQ18: I have already told my family also my friends about it 💗💗 | AR18: 10
A19: 45363.971 | B19: 10 | D19: 10 | F19: 10 | H19: 10 | J19: 10 | L19: 10 | N19: 10 | P19: 10 | R19: 10 | S19: 10 | U19: 10 | W19: 10 | X19: - | Y19: 5 | Z19: - | AA19: 5 | AB19: - | AC19: 3 | AD19: =2*(6-AC19) -> 6 | AE19: - | AF19: - | AG19: 5 | AH19: 2 | AI19: - | AJ19: - | AK19: - | AL19: 5 | AM19: - | AN19: - | AO19: - | AP19: 5 | AQ19: - | AR19: 5
A20: 45363.972 | B20: 10 | D20: 10 | F20: 10 | H20: 10 | J20: 10 | L20: 10 | N20: 10 | P20: 10 | R20: 10 | S20: 10 | U20: 10 | W20: 10 | X20: - | Y20: 5 | Z20: - | AA20: 5 | AB20: - | AC20: 3 | AD20: =2*(6-AC20) -> 6 | AE20: - | AF20: - | AG20: 5 | AH20: 2 | AI20: - | AJ20: - | AK20: - | AL20: 5 | AM20: - | AN20: - | AO20: - | AP20: 5 | AQ20: - | AR20: 5
A21: 45363.972 | B21: 10 | D21: 10 | F21: 10 | H21: 10 | J21: 10 | L21: 10 | N21: 10 | P21: 10 | R21: 10 | S21: 10 | U21: 10 | W21: 10 | X21: - | Y21: 5 | Z21: - | AA21: 5 | AB21: - | AC21: 3 | AD21: =2*(6-AC21) -> 6 | AE21: - | AF21: - | AG21: 5 | AH21: 2 | AI21: - | AJ21: - | AK21: - | AL21: 5 | AM21: - | AN21: - | AO21: - | AP21: 5 | AQ21: - | AR21: 5
A22: 45363.973 | B22: 10 | D22: 10 | F22: 10 | H22: 10 | J22: 10 | L22: 10 | N22: 10 | P22: 10 | R22: 10 | S22: 10 | U22: 10 | W22: 10 | X22: - | Y22: 5 | Z22: - | AA22: 5 | AB22: - | AC22: 4 | AD22: =2*(6-AC22) -> 4 | AE22: - | AF22: - | AG22: 5 | AH22: 2 | AI22: - | AJ22: - | AK22: - | AL22: 5 | AM22: - | AN22: - | AO22: - | AP22: 5 | AQ22: - | AR22: 5
A23: 45363.974 | B23: 10 | D23: 10 | F23: 10 | H23: 10 | J23: 10 | L23: 10 | N23: 10 | P23: 10 | R23: 10 | S23: 10 | U23: 10 | W23: 10 | X23: - | Y23: 5 | Z23: - | AA23: 5 | AB23: - | AC23: 4 | AD23: =2*(6-AC23) -> 4 | AE23: - | AF23: - | AG23: 5 | AH23: 2 | AI23: - | AJ23: - | AK23: - | AL23: 5 | AM23: - | AN23: - | AO23: - | AP23: 5 | AQ23: - | AR23: 5
A24: 45363.975 | B24: 10 | D24: 10 | F24: 10 | H24: 10 | J24: 10 | L24: 10 | N24: 10 | P24: 10 | R24: 10 | S24: 10 | U24: 10 | W24: 10 | X24: - | Y24: 5 | Z24: - | AA24: 5 | AB24: - | AC24: 4 | AD24: =2*(6-AC24) -> 4 | AE24: - | AF24: - | AG24: 5 | AH24: 2 | AI24: - | AJ24: - | AK24: - | AL24: 5 | AM24: - | AN24: - | AO24: - | AP24: 5 | AQ24: - | AR24: 5
A26: Mean | B26: =AVERAGE(B3:B24) -> 8.3181818 | C26: =AVERAGE(C3:C24) -> #DIV/0! | D26: =AVERAGE(D3:D24) -> 9.0454545 | E26: =AVERAGE(E3:E24) -> #DIV/0! | F26: =AVERAGE(F3:F24) -> 8.1818182 | G26: =AVERAGE(G3:G24) -> #DIV/0! | H26: =AVERAGE(H3:H24) -> 9 | I26: =AVERAGE(I3:I24) -> #DIV/0! | ... AB26: =AVERAGE(AB3:AB24) -> #DIV/0! | AD26: =AVERAGE(AD3:AD24) -> 8.2727273 | AE26: =AVERAGE(AE3:AE24) -> #DIV/0! | AF26: =AVERAGE(AF3:AF24) -> #DIV/0! | AG26: =AVERAGE(AG3:AG24) -> 7.4545455 | AH26: =10*AVERAGE(AH3:AH24)/3 -> 7.7272727 | AI26: =AVERAGE(AI3:AI24) -> #DIV/0! | AJ26: =AVERAGE(AJ3:AJ24) -> #DIV/0! | AK26: =AVERAGE(AK3:AK24) -> #DIV/0! | AL26: =AVERAGE(AL3:AL24) -> 7.4545455 | AM26: =AVERAGE(AM3:AM24) -> #DIV/0! | AN26: =AVERAGE(AN3:AN24) -> #DIV/0! | AO26: =AVERAGE(AO3:AO24) -> #DIV/0! | AP26: =AVERAGE(AP3:AP24) -> 8.5454545 | ... AR26: =AVERAGE(AR3:AR24) -> 7.6363636
A27: STD | B27: =_xlfn.STDEV.S(B3:B24) -> 2.1905938 | C27: =_xlfn.STDEV.S(C3:C24) -> #DIV/0! | D27: =_xlfn.STDEV.S(D3:D24) -> 1.7855844 | E27: =_xlfn.STDEV.S(E3:E24) -> #DIV/0! | F27: =_xlfn.STDEV.S(F3:F24) -> 2.2811101 | G27: =_xlfn.STDEV.S(G3:G24) -> #DIV/0! | H27: =_xlfn.STDEV.S(H3:H24) -> 1.5735916 | I27: =_xlfn.STDEV.S(I3:I24) -> #DIV/0! | ... AB27: =_xlfn.STDEV.S(AB3:AB24) -> #DIV/0! | AD27: =_xlfn.STDEV.S(AD3:AD24) -> 2.7112081 | AE27: =_xlfn.STDEV.S(AE3:AE24) -> #DIV/0! | AF27: =_xlfn.STDEV.S(AF3:AF24) -> #DIV/0! | AG27: =_xlfn.STDEV.S(AG3:AG24) -> 1.8446131 | AH27: =10*_xlfn.STDEV.S(AH3:AH24)/3 -> 2.3874371 | AI27: =_xlfn.STDEV.S(AI3:AI24) -> #DIV/0! | AJ27: =_xlfn.STDEV.S(AJ3:AJ24) -> #DIV/0! | AK27: =_xlfn.STDEV.S(AK3:AK24) -> #DIV/0! | AL27: =_xlfn.STDEV.S(AL3:AL24) -> 2.1542267 | AM27: =_xlfn.STDEV.S(AM3:AM24) -> #DIV/0! | AN27: =_xlfn.STDEV.S(AN3:AN24) -> #DIV/0! | AO27: =_xlfn.STDEV.S(AO3:AO24) -> #DIV/0! | AP27: =_xlfn.STDEV.S(AP3:AP24) -> 2.2620529 | ... AR27: =_xlfn.STDEV.S(AR3:AR24) -> 1.9406787
Q29: sample =23 | R29: one sample t-test
Q30: Hypothetical mean value=7
Q31: Question | R31: AVG | S31: STD | T31: SEM | U31: p-value
Q32: Q1 | R32: 8.5 | S32: 2.57 | T32: 0.535 | U32: 0.0105
Q33: Q2 | R33: 8.72 | S33: 2.33 | T33: 0.486 | U33: 0.0018
Q34: Q3 | R34: 9.86 | S34: 0.63 | T34: 0.13 | U34: 0.0001
Q35: Q4 | R35: 9.63 | S35: 1.32 | T35: 0.275 | U35: 0.0001
R38: =AVERAGE(R32:R35) -> 9.1775

Sheet Form responses -raw
B1: Q1 | D1: Q2 | F1: Q3 | H1: Q4 | J1: Q5 | L1: Q6 | N1: Q7 | P1: Q8 | R1: Q9 | S1: Q10 | U1: Q11 | W1: Q12 | X1: Q13 | Y1: Q14 | Z1: Q15 | AA1: Q16 | AB1: Q17 | AC1: Q18 | AD1: Q19 | AE1: Q20 | AF1: Q21 | AG1: Q22 | AH1: Q23 | AI1: Q24
A2: Timestamp | B2: Did you find it easy to find the required buttons? (1 for very hard and 10 for very easy) | C2: Any comment about the point? | D2: Did you recognize different icons and labels? (1 for very hard and 10 for very easy) | E2: Any comment about the point? | F2: Text and colors were easy for the eyes? (1 for no and 10 for yes) | G2: Any comment about the point? | H2: The application is easy to use with minimum instructions from the tester. (1 for no and 10 for yes) | I2: Any comment about the point? | J2: Steps are easy to follow, and buttons are easy to remember (1 for no and 10 for yes) | K2: Any comment about the point? | L2: You managed to finish the tasks as fast as possible. (1 for no and 10 for yes) | M2: Any comment about the point? | N2: Everything was clear and easy to preform without frustration (1 for no and 10 for yes) | O2: Any comment about the point? | P2: You managed to perform well in labs without difficulties in using the VR equipment | Q2: Any comment about the point? | R2: You managed to perform well in labs by hearing ROBO instructions and following them. | S2: ROBO instructions were clear and easy to follow | T2: Any comment about the point? | U2: You found the application interesting. (1 for no and 10 for yes) | V2: Any comment about the point? | W2: You found the gamification functions fun and encouraged competitive behavior. . (1 for no and 10 for yes) | X2: Was the application appealing in term of colors and visuals? | Y2: Was the navigation through the application easy and understandable? | Z2: Was the interface crowded and hard to use? | AA2: Were the icons related to the information presented? | AB2: Does the app appearance consistent? | AC2: was the app fast to preform a task? | AD2: Was it easy to go back to previous pages? | AE2: Could you use the application without instructions? | AF2: Did you manage to achieve the goal of the application? | AG2: What parts of the application did you think represented game aspects and were fun to experience? | AH2: Would you use the application in your education if available to you? | AI2: Would you recommend the application to other people?
A3: 45357.411 | B3: 5 | C3: - | D3: 7 | E3: The text of small bottons that were on the board are soo small and not clear | F3: 7 | G3: Some colors weren't clear (especially when we had to wires) while when i had multiple wires they were clear | H3: 10 | I3: - | J3: 10 | K3: - | L3: 8 | M3: - | N3: 10 | O3: - | P3: 7 | R3: 10 | S3: 10 | U3: 10 | W3: 10 | X3: Yes it was so appealing and the colors/visuals were very attractive | Y3: Yes it was easy and understandable, once you get used to it becomes so much easier | Z3: No, the interface was easy to use and everything is well organized | AA3: Yes they were | AB3: Yes, the only problem was that the text was small for the small parts on the board | AC3: Yes | AD3: Yes | AE3: Yes since there's a hint, you only need to use it for the first time with instructions later there's no need. | AF3: Yes | AG3: Everything was interesting and fun since I don't have any experience in labs. | AH3: Yes sure! | AI3: Definitely yes!
A4: 45357.45 | B4: 8 | C4: No everything easy | D4: 6 | E4: No | F4: 10 | G4: No it was easy | H4: 6 | I4: No | J4: 10 | K4: The hints helped me a lot and it was easy to follow | L4: 9 | M4: No | N4: 7 | O4: Sometimes it lagged but other things were good | P4: 7 | Q4: No | R4: 10 | S4: 10 | T4: The robot was easy to follow with | U4: 10 | V4: First time using this application it was fun | W4: 8 | X4: Yes the colors and visuals were good | Y4: Yes everything was simple and easy with ROBO the robot | Z4: No it was good | AA4: Yes all the information were related | AB4: Yes | AC4: Kind of yes it just lagged a bit | AD4: Yes there was an exit button | AE4: No I used the instructions from the powerpoint | AF4: Yes | AG4: Putting all the chips and wires together | AH4: Yes it helped understanding me where all the wires went | AI4: Yes
A5: 45357.477 | B5: 3 | D5: 4 | F5: 8 | H5: 6 | J5: 9 | L5: 4 | N5: 3 | P5: 4 | R5: 7 | S5: 6 | U5: 10 | V5: Good luck on it 🩷 it is good but the vr tool little bit hard to use | W5: 4 | X5: Yes | Y5: Kind of yes | Z5: Hard to type in | AA5: Yes | AB5: Yes | AC5: No | AD5: No | AE5: No | AF5: Kind of yes | AG5: Starting the circuit | AH5: Yes | AI5: Yes for the it people
A6: 45357.584 | B6: 9 | D6: 10 | F6: 7 | H6: 10 | J6: 10 | L6: 7 | M6: I suggest adding another hand | N6: 6 | O6: It was hard sometimes to focus | P6: 10 | R6: 10 | S6: 10 | T6: Robo was very helpful | U6: 10 | V6: I would like to use it in our labs | W6: 10 | X6: Yes | Y6: Yes | Z6: No | AA6: Yes | AB6: Yes | AC6: Sometime its hard | AD6: Yes | AE6: Maybe after some time of practice | AF6: Yes | AG6: To get the result that i was excepting from the lab | AH6: Yes | AI6: Yes definitely
A7: 45357.615 | B7: 8 | D7: 7 | F7: 5 | G7: The colors weren't very clear they both looked black but I could separate them. And some writing was too small I couldn't read it | H7: 10 | J7: 10 | L7: 8 | N7: 10 | P7: 10 | R7: 10 | S7: 10 | T7: Maybe add captions to the wires so I know where to put them | U7: 10 | V7: Very interesting it was very fun | W7: 10 | X7: Yes | Y7: Yes very clear but the font was too small | Z7: No | AA7: Yes | AB7: Yes | AC7: Yes but a little laggy | AD7: Not really it erased what I wrote before | AE7: Yes | AF7: Yes | AG7: I liked experimenting with the wires and doing the labs and I loved the leaderboard | AH7: Definitely it's very fun | AI7: Yes
A8: 45357.634 | B8: 10 | C8: No | D8: 10 | E8: No | F8: 10 | G8: No | H8: 10 | I8: No | J8: 10 | K8: No | L8: 10 | M8: No | N8: 10 | O8: No | P8: 10 | Q8: No | R8: 10 | S8: 10 | T8: No | U8: 10 | V8: No | W8: 10 | X8: Yes nice | Y8: Sureee | Z8: No | AA8: Yes | AB8: Stable | AC8: Yes | AD8: Yes cool | AE8: Yes | AF8: Yep | AG8: Build | AH8: نعم ينفع جدا خصوصا للصغار | AI8: لاشي
A9: 45357.675 | B9: 9 | C9: somtimes when you click it slips to the other nearby buttons | D9: 10 | F9: 10 | H9: 10 | J9: 10 | L9: 10 | N9: 10 | P9: 9 | Q9: i think the colors of the wires should be a little but brighter | R9: 10 | S9: 10 | U9: 10 | W9: 10 | X9: yes, especially the little robot he was so cute, however the texts sometimes appears shaky especially when you move your head | Y9: it was very easy just like regular mobile apps | Z9: no, it was actually very simple and clear | AA9: yes it was obvious what they represent | AB9: yes, it’s consistent in style and doesn’t look patchy | AC9: yes, but i struggled a tiny bit while pressing buttons since it kinda slip, but overall it’s not that hard or frustrating | AD9: yes you just click a simple back button | AE9: yes since it is clear and already has a cute little instructor (robo) | AF9: yes i built a fully functioning logical circuit | AG9: the limited hearts made me think twice about the placement so i don’t lose, and it’s fun to compete with your colleagues in the leaderboard | AH9: yes, it’s as good as the real lab | AI9: definitely
A10: 45357.773 | B10: 5 | D10: 10 | F10: 5 | H10: 8 | J10: 1 | L10: 1 | N10: 1 | P10: 1 | R10: 10 | S10: 10 | U10: 10 | W10: 10 | X10: Yes | Y10: Yes but by practicing | Z10: No | AA10: Yes | AB10: Yes | AC10: No, I had some difficulty to drag and drop the wires , but again I think by practicing it can be easier to done faster. | AD10: Sometimes, I face difficulties to find back button because it doesn’t show up to me. It shows after I press multiples times. | AE10: Maybe | AF10: Yes | AG10: The physical board with wires and other components. | AH10: Yes, but I suggest to make in Arabic language also the other languages, and about the instructions,I don’t think it enough to understand the subject, put even though it can be improve it by time. | AI10: Yes for sure
A11: 45357.889 | B11: 6 | D11: 10 | E11: Perfect | F11: 8 | H11: 8 | J11: 9 | L11: 9 | N11: 8 | P11: 8 | R11: 9 | S11: 10 | U11: 10 | W11: 10 | X11: Yes | Y11: yes | Z11: No | AA11: Yes | AB11: Yes | AC11: yes | AD11: yes | AE11: I think i need some help | AF11: Yes | AG11: Switching the LED ON AND OFF | AH11: Yes ofc | AI11: yes
A12: 45358.463 | B12: 10 | D12: 10 | F12: 7 | G12: The colors on the wires are a bit dark | H12: 8 | J12: 10 | L12: 10 | N12: 10 | P12: 10 | R12: 10 | S12: 10 | U12: 10 | W12: 10 | X12: Yes | Y12: Very easy | Z12: It wasn't crowder it was all organized and easy to use and easy to follow the instructions | AA12: Yes they were all related | AB12: It was all good and the appearance of the chips but the wire is a bit dark but still easy to know what color of yhe wire is | AC12: Yes | AD12: Yes | AE12: Yes | AF12: Yes | AG12: The part were it showed me that I was wrong in some of the applications and I was very satisfied when it worked | AH12: Yes | AI12: Yes, it helps a lot and shows how it can help knowing how a real bread board works
A13: 45358.536 | B13: 5 | C13: Some buttons are a bit small maybe make them a bit bigger, sometimes there are many buttons so i get confused about which one to choose | D13: 10 | F13: 5 | G13: Yes it was easy for the eyes but the colors of the wires could be made clearer | H13: 8 | J13: 8 | L13: 9 | N13: 9 | P13: 9 | R13: 8 | S13: 8 | U13: 10 | W13: 10 | X13: Yes | Y13: Yes but sometimes i get confused which button to use | Z13: It was good | AA13: Yes | AB13: Yes but the sizes of text and buttons aren’t consistent | AC13: Yes | AD13: I think so | AE13: Probably yes but it might take a bit of time | AF13: Yes | AG13: Learder board time and hearts | AH13: Yess , but i recommend not signing in with email as it takes time to type using vr, maybe use just the id of student | AI13: Yess
A14: 45358.558 | B14: 10 | D14: 10 | F14: 8 | G14: The texts are a bit unclear | H14: 10 | J14: 10 | L14: 8 | N14: 8 | P14: 10 | R14: 10 | S14: 10 | U14: 10 | W14: 10 | X14: Yes | Y14: Yes | Z14: No | AA14: Yes | AB14: Yes | AC14: It glitches when moving fast | AD14: Yes | AE14: Yes | AF14: Yes | AG14: Performing the task was easy and well guided for someone who is playing for the first time | AH14: Yes, the application would make learning much more easier | AI14: Yes
A15: 45358.599 | B15: 8 | D15: 10 | F15: 8 | H15: 10 | J15: 10 | L15: 10 | N15: 10 | P15: 10 | R15: 10 | S15: 10 | U15: 10 | W15: 10 | X15: Yes but the light blue color is too light | Y15: Yes | Z15: No | AA15: Yes | AB15: Yes | AC15: Yes | AD15: Yes | AE15: Yes | AF15: Yes | AG15: The way we can interact to build the circuit with instructions | AH15: Yes | AI15: Yes to kids
A16: 45358.698 | B16: 10 | D16: 9 | F16: 10 | G16: I like how the color is so comfy not red or that colors hurt your eyes | H16: 9 | J16: 10 | L16: 7 | M16: I tried to to do it correctly more that focusing in time | N16: 10 | P16: 10 | R16: 10 | S16: 10 | T16: I did know some information from my background but ROBO reminded me about point that I forget | U16: 10 | W16: 10 | X16: Yes ,it has clear and colorful colors with middle tone not high or low bright . | Y16: It was easy, but sometimes the click button (to go to next steps) I needed to be close more to the display to work successfully . | Z16: No , it has just what needed to be shown. | AA16: Yes , the tools of the experiment was close to the real ones. | AB16: Yes | AC16: Yes | AD16: Yes , there was icon for going back | AE16: For me as IT Student yes I can , even for non IT students easy the application user friendly. | AF16: Yes | AG16: Part of experiment when putting the wires and gets into the breadboard | AH16: Of course, it’s explains everything relate to the course so well as the tools and what needed to use for + the rules of gates etc, it was so good for me. | AI16: Yes they will get interest into VR &IT
A17: 45358.721 | B17: 7 | C17: The structure of the wires needes fixing, it would be better if you provided real photos or demonstrational photos that would should show how it's implemented in real life and regarding to the placing of the wires signals I prefer you put a not on a side on what happened if you miss up or were the pin is heading in the breadboard | D17: 6 | E17: Just the arrangements of wires | F17: 2 | G17: Make it softer which is not too bright | H17: 5 | I17: No | J17: 6 | L17: 8 | M17: The more you get comfortable with the controls the better | N17: 5 | O17: Sometimes lags | P17: 7 | R17: 1 | S17: 8 | U17: 7 | W17: 10 | X17: No not really it was fine | Y17: Yeah | Z17: No | AA17: Yes | AB17: No needs fixing | AC17: No | AD17: Yes there is a bit of a delay | AE17: No but yes without the voice | AF17: Yes | AG17: Placing wires | AH17: Yes | AI17: Yes
A18: 45358.768 | B18: 10 | D18: 10 | F18: 10 | H18: 10 | J18: 10 | L18: 10 | N18: 10 | P18: 10 | R18: 10 | S18: 10 | T18: He was cuteeee i liked him | U18: 10 | V18: I really likked the app , literally everything was amazing | W18: 10 | X18: Yes | Y18: Yes | Z18: nope | AA18: yess | AB18: Yeah | AC18: Reallly fastt | AD18: Yess | AE18: Yes yes | AF18: Of course | AG18: Everything was enjoyable and fun | AH18: Yeahhh I really need it this course its really helpful | AI18: I have already told my family also my friends about it 💗💗
A19: 45363.971 | B19: 10 | D19: 10 | F19: 10 | H19: 10 | J19: 10 | L19: 10 | N19: 10 | P19: 10 | R19: 10 | S19: 10 | U19: 10 | W19: 10 | X19: - | Y19: - | Z19: - | AA19: - | AB19: - | AC19: - | AD19: - | AE19: - | AF19: - | AG19: - | AH19: - | AI19: -
A20: 45363.972 | B20: 10 | D20: 10 | F20: 10 | H20: 10 | J20: 10 | L20: 10 | N20: 10 | P20: 10 | R20: 10 | S20: 10 | U20: 10 | W20: 10 | X20: - | Y20: - | Z20: - | AA20: - | AB20: - | AC20: - | AD20: - | AE20: - | AF20: - | AG20: - | AH20: - | AI20: -
A21: 45363.972 | B21: 10 | D21: 10 | F21: 10 | H21: 10 | J21: 10 | L21: 10 | N21: 10 | P21: 10 | R21: 10 | S21: 10 | U21: 10 | W21: 10 | X21: - | Y21: - | Z21: - | AA21: - | AB21: - | AC21: - | AD21: - | AE21: - | AF21: - | AG21: - | AH21: - | AI21: -
A22: 45363.973 | B22: 10 | D22: 10 | F22: 10 | H22: 10 | J22: 10 | L22: 10 | N22: 10 | P22: 10 | R22: 10 | S22: 10 | U22: 10 | W22: 10 | X22: - | Y22: - | Z22: - | AA22: - | AB22: - | AC22: - | AD22: - | AE22: - | AF22: - | AG22: - | AH22: - | AI22: -
A23: 45363.974 | B23: 10 | D23: 10 | F23: 10 | H23: 10 | J23: 10 | L23: 10 | N23: 10 | P23: 10 | R23: 10 | S23: 10 | U23: 10 | W23: 10 | X23: - | Y23: - | Z23: - | AA23: - | AB23: - | AC23: - | AD23: - | AE23: - | AF23: - | AG23: - | AH23: - | AI23: -
A24: 45363.975 | B24: 10 | D24: 10 | F24: 10 | H24: 10 | J24: 10 | L24: 10 | N24: 10 | P24: 10 | R24: 10 | S24: 10 | U24: 10 | W24: 10 | X24: - | Y24: - | Z24: - | AA24: - | AB24: - | AC24: - | AD24: - | AE24: - | AF24: - | AG24: - | AH24: - | AI24: -

Sheet UsabilityScaleOrigin
A6: Criteria | B6: Survey Question (s)
A7: User Interface Usage and Complexity | B7: Q1. Did you find it easy to find the required buttons? (1 for very hard and 10 for very easy)
B8: Q2. Did you recognize different icons and labels? (1 for very hard and 10 for very easy)
B9: Q10. Were ROBO instructions clear and easy to follow?
B10: Q15. Was the App interface crowded and hard to use?
A11: Memorability | B11: Q5. Steps are easy to follow, and buttons are easy to remember (1 for no and 10 for yes)
A12: Tension and Frustration | B12: Q7. Was everything clear and easy to preform without frustration (1 for no and 10 for yes)?
A13: Learnability and Technician person need | B13: Q4. The application is easy to use with minimum instructions from the tester. (1 for no and 10 for yes)
A14: System/interface Consistency | B14: Q17. Is the app appearance consistent?
A15: Performance (learning speed) | B15: Q6. Did you manage to finish the tasks as fast as possible (1 for no and 10 for yes)?
A16: Usage cumbersomeness. | B16: Q8. Did you manage to perform well in labs without difficulties in using the VR equipment?
A17: User Confidence | B17: Q9. Did you manage to perform well in labs by hearing ROBO instructions and following them?
A18: Prior knowledge and training | B18: Q14. Was the navigation through the application easy and understandable?
B19: Q20. Could you use the application without instructions?
A20: Brightness and Colouring | B20: Q3. Text and colors were easy for the eyes? (1 for no and 10 for yes)
B21: Q13. Was the application appealing in term of colors and visuals?
A22: Satisfaction and Engagement | B22: Q11. You found the application interesting. (1 for no and 10 for yes)
B23: Q12. You found the gamification functions fun and encouraged competitive behavior. (1 for no and 10 for yes)
A24: Recommending the App | B24: Q23. Would you use the application in your education if available to you?
B25: Q24. Would you recommend the application to other people?
A27: Criteria | B27: Survey Question (s) | C27: AVG | D27: STD
A28: User Interface Usage and Complexity | B28: Q1, Q2, Q10, and Q15 | C28: 8.18 | D28: 1.32
A29: Memorability | B29: Q5 | C29: 9.22 | D29: 2.06
A30: Tension and Frustration | B30: Q7 | C30: 8.5 | D30: 2.57
A31: Learnability & technician person need | B31: Q4 | C31: 9 | D31: 1.57
A32: System/interface Consistency | B32: Q17 | C32: 7.45 | D32: 1.84
A33: Performance (Learning Speed) | B33: Q6 | C33: 8.54 | D33: 2.26
A34: Usage cumbersomeness. | B34: Q8 | C34: 8.72 | D34: 2.33
A35: User Confidence | B35: Q9 | C35: 9.31 | D35: 2
A36: Prior knowledge and training | B36: Q14, Q20 | C36: 7.45 | D36: 1.81
A37: Brightness and Colouring | B37: Q3, Q13 | C37: 7.9 | D37: 1.25
A38: Satisfaction and Engagement | B38: Q11, A12 | C38: 9.75 | D38: 0.71
A39: Recommending the App | B39: Q23, Q24 | C39: 8.09 | D39: 2.02
A40: Overall Usability | C40: 0.8566 | D40: 10.66

Sheet UsabilityScale
A1: Q1 | B1: Q2 | C1: Q5 | D1: Q15 | F1: Q7 | G1: Q10 | I1: Q4 | J1: Q17 | K1: Q6 | L1: Q8 | M1: Q9 | N1: Q14 | O1: Q20 | Q1: Q3 | R1: Q13 | T1: Q11 | U1: Q12 | W1: Q23 | X1: Q24
